Tue Dec 11 11:16:41 EST 2018
Traceback (most recent call last):
  File "./master", line 117, in <module>
    output=praxis(tolerance, max_step, 11, 4, param, loop)
  File "praxis/praxis.py", line 904, in praxis
    fx = f ( x, n )
  File "./master", line 90, in loop
    error = get_error(data)
  File "./master", line 40, in get_error
    w(str(dat.R['ener'])+' '+str(dat.E['ener'])+' '+str(dE))
KeyError: 'ener'
